Thank you, Claude,

I updated the wsgi.py file as you recommended and saved it to my /home/nickspi5/Chatty_AI folder

I then ran: (chatty-venv) nickspi5@raspberrypi1:~/Chatty_AI $ gunicorn --check-config --config gunicorn_config.py wsgi:app
2025-08-16 13:18:49,974 - INFO - ChattyAI Web Server initialized

Error while loading the application:

Traceback (most recent call last):
  File "/home/nickspi5/Chatty_AI/chatty-venv/lib/python3.11/site-packages/gunicorn/app/base.py", line 207, in run
    self.load()
  File "/home/nickspi5/Chatty_AI/chatty-venv/lib/python3.11/site-packages/gunicorn/app/wsgiapp.py", line 57, in load
    return self.load_wsgiapp()
           ^^^^^^^^^^^^^^^^^^^
  File "/home/nickspi5/Chatty_AI/chatty-venv/lib/python3.11/site-packages/gunicorn/app/wsgiapp.py", line 47, in load_wsgiapp
    return util.import_app(self.app_uri)
           ^^^^^^^^^^^^^^^^^^^^^^^^^^^^^
  File "/home/nickspi5/Chatty_AI/chatty-venv/lib/python3.11/site-packages/gunicorn/util.py", line 441, in import_app
    raise AppImportError("Application object must be callable.")
gunicorn.errors.AppImportError: Application object must be callable.
(chatty-venv) nickspi5@raspberrypi1:~/Chatty_AI $ 








